<?xml version="1.0" ?>
<robot xmlns:xacro="http://ros.org/wiki/xacro">

  <!--
  <xacro:property name="pi" value="3.141592654" />
  -->

  <!-- head -->
  <xacro:macro name="robotis_op2_head" params="parent">

  <!-- head yaw joint -->  <!--ok-->
  <joint name="head_pan" type="revolute">
    <parent link="${parent}"/>
    <child link="head_pan_link"/>
    <origin xyz="0 0 0.0235" rpy="0 0 1.5707963" />
    <axis xyz="0 0 1" />
    <limit effort="2.8" velocity="5.6548668" lower="-2.6179939" upper="2.6179939" />
    <dynamics damping="0.1" friction="0.0" />
  </joint>
  <xacro:insert_transmission name="head_pan" />
 
  <!-- head yaw link -->  <!--ok-->
  <link name="head_pan_link">
    <visual>
      <xacro:insert_mesh_head_pan_link />
    </visual>
    <collision>
      <xacro:insert_coll_head_pan_link />
    </collision>
    <inertial>
      <xacro:insert_inertia_head_pan_link />
    </inertial>
  </link>

  <!-- head pitch joint -->  <!--ok-->
  <joint name="head_tilt" type="revolute">
    <parent link="head_pan_link"/>
    <child link="head_tilt_link"/>
    <origin xyz="0 0 0.02715" rpy="-1.5707963 0 1.5707963" />
    <axis xyz="0 0 1" />
    <limit effort="2.8" velocity="5.6548668" lower="-2.6179939" upper="2.6179939" />
    <dynamics damping="0.1" friction="0.0" />
  </joint>
  <xacro:insert_transmission name="head_tilt" />

  <!-- head yaw link -->  <!--ok-->
  <link name="head_tilt_link">
    <visual>
      <xacro:insert_mesh_head_tilt_link />
    </visual>
    <collision>
      <xacro:insert_coll_head_tilt_link />
    </collision>
    <inertial>
      <xacro:insert_inertia_head_tilt_link />
    </inertial>
  </link>

  <!-- camera joint -->
  <joint name="cam" type="fixed">
    <origin xyz="0 0 0.0235" rpy="${-pi*0.5} 0 ${-pi*0.5}"/>
    <parent link="head_tilt_link"/>
    <child link="cam_link"/>
  </joint>

  <joint name="cam_gazebo" type="fixed">
	  <!-- origin can be more precise to match real robot-->
    <origin xyz="-0.042 -0.016 0" rpy="0 ${pi} ${-pi*0.05}"/>
    <axis xyz="0 0 1" />    
    <parent link="head_tilt_link"/>
    <child link="cam_gazebo_link"/>
  </joint>

  <!-- camera link -->
  <link name="cam_link">
  </link>

  <!-- camera link -->
  <link name="cam_gazebo_link">
  </link>

  </xacro:macro>

</robot>
