<?xml version="1.0" ?>
<robot xmlns:xacro="http://ros.org/wiki/xacro">

  <!--
  <xacro:property name="pi" value="3.141592654" />
  -->

  <!-- left leg -->
  <xacro:macro name="robotis_op2_l_leg" params="parent">

  <!-- left hip yaw joint -->
  <joint name="l_hip_yaw" type="revolute">
    <parent link="${parent}"/>
    <child link="l_hip_yaw_link"/>
    <origin xyz="-0.005 0.037 -0.09355" rpy="0 3.14159 -1.5707963" />
    <axis xyz="0 0 1" />
    <limit effort="10" velocity="5.6548668" lower="${-pi*0.9}" upper="${pi*0.9}" />
    <dynamics damping="0.1" friction="0.0" />
  </joint>
  <xacro:insert_transmission name="l_hip_yaw" />

  <!-- left hip yaw link -->
  <link name="l_hip_yaw_link">
    <visual>
      <xacro:insert_mesh_l_hip_yaw_link />
    </visual>
    <collision>
      <xacro:insert_mesh_l_hip_yaw_link />
    </collision>
    <inertial>
      <xacro:insert_inertia_l_hip_yaw_link />
    </inertial>
  </link>

  <!-- left hip roll joint -->
  <joint name="l_hip_roll" type="revolute">
    <parent link="l_hip_yaw_link"/>
    <child link="l_hip_roll_link"/>
    <origin xyz="0 0 0.028652" rpy="1.5707963 0 0" />
    <axis xyz="0 0 1" />
    <limit effort="10" velocity="5.6548668" lower="${-pi*0.9}" upper="${pi*0.9}" />
    <dynamics damping="0.1" friction="0.0" />
  </joint>
  <xacro:insert_transmission name="l_hip_roll" />

  <!-- left hip roll link -->
  <link name="l_hip_roll_link">
    <visual>
      <xacro:insert_mesh_l_hip_roll_link />
    </visual>
    <collision>
      <xacro:insert_mesh_l_hip_roll_link />
    </collision>
    <inertial>
      <xacro:insert_inertia_l_hip_roll_link />
    </inertial>
  </link>

  <!-- left hip pitch joint -->
  <joint name="l_hip_pitch" type="revolute">
    <parent link="l_hip_roll_link"/>
    <child link="l_hip_pitch_link"/>
    <origin xyz="0 0 0" rpy="1.5707963 0 -1.5707963" />
    <axis xyz="0 0 1" />
    <limit effort="10" velocity="5.6548668" lower="${-pi*0.9}" upper="${pi*0.9}" />
    <dynamics damping="0.1" friction="0.0" />
  </joint>
  <xacro:insert_transmission name="l_hip_pitch" />

  <!-- left hip pitch link -->
  <link name="l_hip_pitch_link">
    <visual>
      <xacro:insert_mesh_l_hip_pitch_link />
    </visual>
    <collision>
      <xacro:insert_mesh_l_hip_pitch_link />
    </collision>
    <inertial>
      <xacro:insert_inertia_l_hip_pitch_link />
    </inertial>
  </link>

  <!-- left knee joint -->
  <joint name="l_knee" type="revolute">
    <parent link="l_hip_pitch_link"/>
    <child link="l_knee_link"/>
    <origin xyz="-0.093 0 0" rpy="0 0 0" />
    <axis xyz="0 0 1" />
    <limit effort="10" velocity="5.6548668" lower="${-pi*0.9}" upper="${pi*0.9}" />
    <dynamics damping="0.1" friction="0.0" />
  </joint>
  <xacro:insert_transmission name="l_knee" />

  <!-- left hip pitch link -->
  <link name="l_knee_link">
    <visual>
      <xacro:insert_mesh_l_knee_link />
    </visual>
    <collision>
      <xacro:insert_mesh_l_knee_link />
    </collision>
    <inertial>
      <xacro:insert_inertia_l_knee_link />
    </inertial>
  </link>

  <!-- left ankle pitch link -->
  <joint name="l_ank_pitch" type="revolute">
    <parent link="l_knee_link"/>
    <child link="l_ank_pitch_link"/>
    <origin xyz="-0.093 0 0" rpy="3.14159 0 0" />
    <axis xyz="0 0 1" />
    <limit effort="10" velocity="5.6548668" lower="${-pi*0.9}" upper="${pi*0.9}" />
    <dynamics damping="0.1" friction="0.0" />
  </joint>
  <xacro:insert_transmission name="l_ank_pitch" />

  <!-- left hip pitch link -->
  <link name="l_ank_pitch_link">
    <visual>
      <xacro:insert_mesh_l_ank_pitch_link />
    </visual>
    <collision>
      <xacro:insert_mesh_l_ank_pitch_link />
    </collision>
    <inertial>
      <xacro:insert_inertia_l_ank_pitch_link />
    </inertial>
  </link>

  <!-- left ankle roll link -->
  <joint name="l_ank_roll" type="revolute">
    <parent link="l_ank_pitch_link"/>
    <child link="l_ank_roll_link"/>
    <origin xyz="0 0 0" rpy="-1.5707963 0 0" />
    <axis xyz="0 0 1" />
    <limit effort="10" velocity="5.6548668" lower="${-pi*0.9}" upper="${pi*0.9}" />
    <dynamics damping="0.1" friction="0.0" />
  </joint>
  <xacro:insert_transmission name="l_ank_roll" />

  <!-- left hip roll link -->
  <link name="l_ank_roll_link">
    <visual>
      <xacro:insert_mesh_l_ank_roll_link />
    </visual>
    <collision>
      <xacro:insert_mesh_l_ank_roll_link />
    </collision>
    <inertial>
      <xacro:insert_inertia_l_ank_roll_link />
    </inertial>
  </link>

  </xacro:macro>

</robot>
