<?xml version="1.0" ?>
<robot xmlns:xacro="http://ros.org/wiki/xacro">

  <!--
  <xacro:property name="pi" value="3.141592654" />
  -->
  <xacro:arg name="with_hand" default="false" />  
  
  <!-- right arm -->
  <xacro:macro name="robotis_op2_r_arm" params="parent">

  <joint name="r_back" type="fixed">
    <parent link="${parent}"/>
    <child link="r_back_link"/>
    <origin xyz="0 -0.06035 0" rpy="1.5707963 0 0" />
    <limit effort="2.8" velocity="5.6548668" lower="-2.6179939" upper="2.6179939" />
  </joint>

  <!-- right back link -->
  <link name="r_back_link">
    <visual>
      <xacro:insert_mesh_r_back_link />
    </visual>
    <collision>
      <xacro:insert_coll_r_back_link />
    </collision>
    <inertial>
      <xacro:insert_inertia_r_back_link />
    </inertial>
  </link>

  <!-- right shoulder pitch joint -->
  <joint name="r_sho_pitch" type="revolute">
    <parent link="r_back_link"/>
    <child link="r_sho_pitch_link"/>
    <origin xyz="0 0 0" rpy="0 0 -1.5707963" />
    <axis xyz="0 0 1" />
    <limit effort="2.8" velocity="5.6548668" lower="-2.6179939" upper="2.6179939" />
    <dynamics damping="0.1" friction="0.0" />
  </joint>
  <xacro:insert_transmission name="r_sho_pitch" />

  <!-- right shoulder pitch link -->
  <link name="r_sho_pitch_link">
    <visual>
      <xacro:insert_mesh_r_sho_pitch_link />
    </visual>
    <collision>
      <xacro:insert_mesh_r_sho_pitch_link />
    </collision>
    <inertial>
      <xacro:insert_inertia_r_sho_pitch_link />
    </inertial>
  </link>

  <!-- right shoulder roll joint -->
  <joint name="r_sho_roll" type="revolute">
    <parent link="r_sho_pitch_link"/>
    <child link="r_sho_roll_link"/>
    <origin xyz="0.016 0 0.02165" rpy="-1.5707963 ${pi*0.75} 0" />
    <axis xyz="0 0 -1" />
    <limit effort="2.8" velocity="5.6548668" lower="-2.6179939" upper="2.6179939" />
    <dynamics damping="0.1" friction="0.0" />
  </joint>
  <xacro:insert_transmission name="r_sho_roll" />

  <!-- right shoulder roll link -->
  <link name="r_sho_roll_link">
    <visual>
      <xacro:insert_mesh_r_sho_roll_link />
    </visual>
    <collision>
      <xacro:insert_mesh_r_sho_roll_link />
    </collision>
    <inertial>
      <xacro:insert_inertia_r_sho_roll_link />
    </inertial>
  </link>

  <!-- right elbow joint --><!--ok-->
  <joint name="r_el" type="revolute">
    <parent link="r_sho_roll_link"/>
    <child link="r_el_link"/>
    <origin xyz="-0.06 0 0.016" rpy="-1.5707963 ${pi*-4/8} 0" />
    <axis xyz="0 0 1" />
    <limit effort="2.8" velocity="5.6548668" lower="-1.635" upper="2.6179939" />
    <dynamics damping="0.1" friction="0.0" />
  </joint>
  <xacro:insert_transmission name="r_el" />

  <!-- right elbow link -->
  <link name="r_el_link">
    <visual>
      <xacro:insert_mesh_r_el_link />
    </visual>
    <collision>
      <xacro:insert_mesh_r_el_link />
    </collision>
    <inertial>
      <xacro:insert_inertia_r_el_link />
    </inertial>
  </link>



  <xacro:if value="$(arg with_hand)">

  <!-- right wrist1 joint -->
  <joint name="r_wrist1" type="continuous">
    <parent link="r_el_link"/>
    <child link="r_wrist1_link"/>
    <origin xyz="0.1285 -0.016 0" rpy="0 0 0" />
    <axis xyz="1 0 0" />
    <limit effort="2.8" velocity="5.6548668" />
    <dynamics damping="0.1" friction="0.0" />      
  </joint>
<!--  <xacro:insert_transmission name="l_el" />-->

  <!-- right wrist1 link -->
  <link name="r_wrist1_link">
    <visual>
      <xacro:insert_mesh_r_wrist_link />
    </visual>
    <collision>
      <xacro:insert_coll_r_wrist_link />
    </collision>
    <inertial>
      <xacro:insert_inertia_r_wrist_link />
    </inertial>
  </link>

  <!-- right wrist2 joint -->
  <joint name="r_wrist2" type="continuous">
    <parent link="r_wrist1_link"/>
    <child link="r_wrist2_link"/>
    <origin xyz="0.001 0 0" rpy="0 0 0" />
    <axis xyz="0 1 0" />
    <limit effort="2.8" velocity="5.6548668" />
    <dynamics damping="0.1" friction="0.0" />      
  </joint>

  <!-- right wrist2 link -->
  <link name="r_wrist2_link">
    <visual>
      <xacro:insert_mesh_r_wrist_link />
    </visual>
    <collision>
      <xacro:insert_coll_r_wrist_link />
    </collision>
    <inertial>
      <xacro:insert_inertia_r_wrist_link />
    </inertial>
  </link>


  <!-- right wrist3 joint -->
  <joint name="r_wrist3" type="continuous">
    <parent link="r_wrist2_link"/>
    <child link="r_hand_link"/>
    <origin xyz="0.001 0 0" rpy="0 0 0" />
    <axis xyz="0 0 1" />
    <limit effort="2.8" velocity="5.6548668" />
    <dynamics damping="0.1" friction="0.0" />      
  </joint>

  <!-- right hand link -->
  <link name="r_hand_link">
    <visual>
      <xacro:insert_mesh_r_hand_link />
    </visual>
    <collision>
      <xacro:insert_coll_r_hand_link />
    </collision>
    <inertial>
      <xacro:insert_inertia_r_hand_link />
    </inertial>
  </link>
  
  </xacro:if>

  </xacro:macro>

</robot>
